Workbook

Sheet 09_DanhMuc
A1: DANH MỤC DÙNG CHO DROPDOWN — KHÔNG CẦN CHỈNH SỬA
A2: Trạng thái | B2: Vai trò công việc | C2: Độ khó | D2: Điểm 1–5 | E2: Có/Không | F2: Loại minh chứng | G2: Nhóm nội dung | H2: Mức độ yêu cầu | I2: Kết quả kiểm tra | J2: Loại thành viên
A3: Chưa làm | B3: Chính | C3: 1 | D3: 1 | E3: Có | F3: Commit | G3: Blueprint | H3: Bắt buộc | I3: Đạt | J3: Khán giả
A4: Đang làm | B4: Phối hợp | C4: 2 | D4: 2 | E4: Không | F4: Pull request | G4: Cài đặt | H4: Chọn ít nhất 2 luồng | I4: Chưa đạt | J4: Ban tổ chức
A5: Hoàn thành | B5: Hỗ trợ | C5: 3 | D5: 3 | F5: Source code | G5: Kiểm thử | H5: Khuyến nghị | I5: Chưa kiểm tra | J5: Nhân sự soát vé
A6: Không áp dụng | C6: 4 | D6: 4 | F6: Sơ đồ | G6: Nộp bài | I6: Không áp dụng
C7: 5 | D7: 5 | F7: Tài liệu | G7: Vấn đáp
F8: Test report
F9: Ảnh chụp
F10: Video demo
F11: Google Drive
F12: Khác

Sheet 00_HuongDan
A1: HƯỚNG DẪN ĐIỀN FILE TỰ ĐÁNH GIÁ ĐỒ ÁN TICKETBOX
A3: Mục đích: Nhóm sinh viên tự khai báo đầy đủ phần việc, minh chứng và mức độ đóng góp. Giảng viên dùng file này để kiểm tra và vấn đáp; nội dung khai báo phải khớp với source code, Blueprint và video.
A5: Bước | B5: Sheet cần điền | C5: Sinh viên thực hiện | D5: Yêu cầu tối thiểu
A6: 1 | B6: 01_ThongTinNhom | C6: Điền thông tin nhóm, 1–4 thành viên và các link nộp bài. | D6: Link Google Drive phải public và mở được.
A7: 2 | B7: 02_ChecklistYeuCau | C7: Đối chiếu từng yêu cầu TicketBox; chọn owner, trạng thái, % hoàn thành và dán minh chứng. | D7: Không ghi “đã làm” nếu không có link/path minh chứng.
A8: 3 | B8: 03_PhanCongTask | C8: Tách công việc đủ nhỏ để phân biệt đóng góp cá nhân. | D8: Mỗi task phải có sản phẩm đầu ra và tiêu chí hoàn thành.
A9: 4 | B9: 04_TuDanhGia | C9: Mỗi thành viên tự chấm 1–5 và mô tả 3 đóng góp quan trọng nhất. | D9: Không tự chấm 5 nếu không thể giải thích khi vấn đáp.
A10: 5 | B10: 05_DanhGiaCheo | C10: Các thành viên đánh giá chéo, nêu lý do và ví dụ cụ thể. | D10: Nhóm 1 người để trống sheet này.
A11: 6 | B11: 06_MinhChung_NopBai | C11: Liệt kê commit/PR/tài liệu/sơ đồ/test/video và kiểm tra cấu trúc Google Drive. | D11: Mỗi minh chứng phải có người thực hiện và cách kiểm tra.
A12: 7 | B12: 07_ChuanBiVanDap | C12: Phân công thành viên chuẩn bị giải thích các quyết định kiến trúc và cơ chế kỹ thuật. | D12: Người phụ trách phải hiểu code, không chỉ đọc slide.
A13: 8 | B13: 08_TongHopGV | C13: Xem % tiến độ toàn nhóm, % hoàn thành đủ minh chứng và cảnh báo đóng góp cá nhân. | D13: Ưu tiên chỉ số “Hoàn thành đủ minh chứng”; các mục Không áp dụng không tính vào mẫu số.
A15: QUY ƯỚC MÀU
A16: Màu vàng | B16: Ô sinh viên cần điền
A17: Màu xám | B17: Ô công thức/tổng hợp — không sửa
A18: Màu xanh lá | B18: Thông tin hướng dẫn hoặc mục đã đạt
A19: Màu đỏ nhạt | B19: Thông tin bắt buộc/cảnh báo
A21: NGUỒN ĐẶC TẢ
A22: Đặc tả TicketBox | B22: https://nndkhoa.github.io/software-design-docs/exercises/project/spec-ticketbox.html
A23: Lưu ý | B23: File đánh giá này diễn giải yêu cầu để sinh viên tự khai báo; không thay thế đặc tả chính thức.

Sheet 01_ThongTinNhom
A1: THÔNG TIN NHÓM VÀ LINK NỘP BÀI
A3: A. THÔNG TIN CHUNG
A4: Mã nhóm * | C4: Lớp * | E4: Tên đồ án | F4: TicketBox | G4: Ngày cập nhật | H4: 46218
A5: Tên nhóm | B5: Com Ga Xoi Mo | C5: Số thành viên | D5: =COUNTIFS(B16:B19,"<>",G16:G19,"Có") | E5: Link repository * | F5: https://github.com/com-ga-xoi-mo/ticketbox-system | G5: Nhánh/Tag nộp | H5: main
A6: Link Google Drive public * | E6: Link Blueprint
A7: Link thư mục source/src | E7: Link thư mục clips/video
A8: Link demo đang chạy (nếu có) | E8: Link tài liệu khác
A10: Link Google Drive phải bật quyền “Anyone with the link/Người có đường liên kết — Viewer”. Thư mục phải có đủ: (1) blueprint.pdf hoặc blueprint/, (2) src/ + data/ + README.md, (3) clips/ chứa video MP4 có camera thành viên và demo trực tiếp.
A14: B. DANH SÁCH THÀNH VIÊN — CHỈ ĐIỀN ĐÚNG SỐ NGƯỜI THỰC TẾ (1–4)
A15: STT | B15: Họ và tên * | C15: MSSV * | D15: Email | E15: Vai trò chính | F15: GitHub username | G15: Tham gia nhóm? | H15: Ghi chú
A16: 1 | B16: Nguyễn Bảo An | C16: 23120207 | D16: baoan1real1@gmail.com | E16: Kiến trúc / Backend nền tảng | F16: NgBaoAnn | G16: Có | H16: Người đại diện. Blueprint, C4, ERD, ADR; RBAC; platform foundation; seed; audience-web.
A17: 2 | B17: Phạm Quang Vinh | C17: 23120202 | D17: vinhp1546@gmail.com | E17: Backend Catalog / Frontend Admin | F17: vinh-code | G17: Có | H17: Concert catalog, caching Redis, quản trị concert/admin web, seating map SVG. Hỗ trợ UI AI bio.
A18: 3 | B18: Nguyễn Lê Thế Vinh | C18: 23120190 | D18: nguyenlethevinh14@gmail.com | E18: Mobile Check-in / Tích hợp (AI, CSV, Notification) | F18: tzin1401 | G18: Có | H18: App soát vé RN, offline sync, AI Artist Bio, import CSV Guest List, notification đa kênh.
A19: 4 | B19: Trương Nhật Đạt | C19: 23120231 | D19: nhatdat2905@gmail.com | E19: Backend Giao dịch & Thanh toán | F19: nhaajtdajt | G19: Có | H19: Chống oversell, giới hạn vé/user, payment (idempotency, circuit breaker), rate limiting, checkout.
A21: C. XÁC NHẬN CỦA NHÓM
A22: Cam kết | B22: Nhóm xác nhận các thông tin, link và tỷ lệ đóng góp trong file là đúng; mỗi thành viên có thể giải thích phần việc đã khai báo.
A23: Người đại diện | B23: Nguyễn Bảo An | C23: Ngày xác nhận | D23: 46218 | E23: Trạng thái link Drive | F23: Chưa có | G23: Đã kiểm tra trên thiết bị khác? | H23: Không
A24: Ghi chú | B24: Chưa tạo Google Drive nộp bài. Blueprint/source/README hiện nằm trong repo GitHub; nhóm sẽ đẩy lên Drive public và merge dev -> main trước khi nộp.

Sheet 02_ChecklistYeuCau
A1: CHECKLIST ĐỐI CHIẾU YÊU CẦU ĐỒ ÁN TICKETBOX
A3: Điền theo sản phẩm thực tế. “Tiến độ tự khai” là trung bình cột % HT. “Hoàn thành đủ minh chứng” chỉ tính mục có trạng thái Hoàn thành, tự kiểm tra Đạt và có link/path minh chứng. Mục “Không áp dụng” được loại khỏi mẫu số.
A4: TIẾN ĐỘ TỰ KHAI | B4: =IFERROR(SUMIFS($H$6:$H$43,$G$6:$G$43,"<>Không áp dụng")/(COUNTIFS($A$6:$A$43,"<>",$G$6:$G$43,"<>Không áp dụng"))/100,0) | C4: HOÀN THÀNH 100% | D4: =IFERROR(COUNTIFS($G$6:$G$43,"Hoàn thành")/(COUNTIFS($A$6:$A$43,"<>",$G$6:$G$43,"<>Không áp dụng")),0) | E4: TỰ KIỂM TRA ĐẠT | F4: =IFERROR(COUNTIFS($J$6:$J$43,"Đạt",$G$6:$G$43,"<>Không áp dụng")/(COUNTIFS($A$6:$A$43,"<>",$G$6:$G$43,"<>Không áp dụng")),0) | G4: CÓ MINH CHỨNG | H4: =IFERROR(COUNTIFS($I$6:$I$43,"<>",$G$6:$G$43,"<>Không áp dụng")/(COUNTIFS($A$6:$A$43,"<>",$G$6:$G$43,"<>Không áp dụng")),0) | I4: HOÀN THÀNH ĐỦ MINH CHỨNG | J4: =IFERROR(COUNTIFS($G$6:$G$43,"Hoàn thành",$J$6:$J$43,"Đạt",$I$6:$I$43,"<>")/(COUNTIFS($A$6:$A$43,"<>",$G$6:$G$43,"<>Không áp dụng")),0) | K4: Xem chi tiết tại 08_TongHopGV
A5: ID | B5: Nhóm | C5: Mức độ | D5: Yêu cầu cần chứng minh | E5: Minh chứng mong đợi | F5: Owner | G5: Trạng thái | H5: % HT | I5: Link/Path minh chứng | J5: Kết quả tự kiểm tra | K5: Ghi chú/lỗi còn lại
A6: BP01 | B6: Blueprint | C6: Bắt buộc | D6: Tài liệu mô tả kiến trúc tổng thể, thành phần, giao tiếp, ảnh hưởng khi một phần lỗi. | E6: design.md/blueprint.pdf; lập luận lựa chọn kiến trúc | F6: Nguyễn Bảo An | G6: Hoàn thành | H6: 100 | I6: blueprint/design.md — Context + Decisions 1–12 (kiến trúc, giao tiếp, failure boundary) | J6: Đạt
A7: BP02 | B7: Blueprint | C7: Bắt buộc | D7: C4 Level 1 – System Context: actors và hệ thống ngoài. | E7: Sơ đồ + mô tả Khán giả, Ban tổ chức, Soát vé, VNPAY/MoMo, AI, CSV | F7: Nguyễn Bảo An | G7: Hoàn thành | H7: 100 | I7: blueprint/design.md — mục "C4 Level 1: System Context" | J7: Đạt
A8: BP03 | B8: Blueprint | C8: Bắt buộc | D8: C4 Level 2 – Container: web, mobile, backend, database, broker/cache... | E8: Sơ đồ có công nghệ và giao tiếp giữa container | F8: Nguyễn Bảo An | G8: Hoàn thành | H8: 100 | I8: blueprint/design.md — mục "C4 Level 2: Container" | J8: Đạt
A9: BP04 | B9: Blueprint | C9: Bắt buộc | D9: High-Level Architecture Diagram, nhấn mạnh payment, AI, CSV và offline check-in. | E9: Sơ đồ luồng dữ liệu/phụ thuộc và failure boundary | F9: Nguyễn Bảo An | G9: Hoàn thành | H9: 100 | I9: blueprint/design.md — mục "High-Level Architecture Flow" (sơ đồ mermaid) | J9: Đạt
A10: BP05 | B10: Blueprint | C10: Bắt buộc | D10: Thiết kế dữ liệu: SQL/NoSQL/kết hợp và schema entity quan trọng. | E10: ERD/schema + giải thích lựa chọn và consistency | F10: Nguyễn Bảo An | G10: Hoàn thành | H10: 100 | I10: blueprint/design.md — mục "Database Design"; prisma/schema.prisma | J10: Đạt
A11: BP06 | B11: Blueprint | C11: Chọn ít nhất 2 luồng | D11: Luồng mua vé từ bấm mua đến nhận e-ticket; có xử lý lỗi giữa chừng. | E11: Sequence/activity diagram hoặc mô tả bước + lỗi | F11: Nguyễn Bảo An | G11: Hoàn thành | H11: 100 | I11: blueprint/design.md — "Ticket purchase from buy click to e-ticket" (gồm xử lý lỗi giữa chừng) | J11: Đạt
A12: BP07 | B12: Blueprint | C12: Chọn ít nhất 2 luồng | D12: Luồng soát vé mất mạng và đồng bộ lại; tránh vé vào hai lần. | E12: Sequence/state diagram + conflict handling | F12: Nguyễn Lê Thế Vinh | G12: Hoàn thành | H12: 100 | I12: blueprint/design.md — "Offline check-in and sync"; docs/manual-tests/checkin-offline-sync.md | J12: Đạt
A13: BP08 | B13: Blueprint | C13: Chọn ít nhất 2 luồng | D13: Luồng nhập Guest List CSV; xử lý file lỗi và dữ liệu trùng. | E13: Flow + validation + idempotent import | F13: Nguyễn Lê Thế Vinh | G13: Hoàn thành | H13: 100 | I13: blueprint/design.md — "Guest list CSV import"; docs/manual-tests/guest-list-import.md | J13: Đạt
A14: BP09 | B14: Blueprint | C14: Bắt buộc | D14: Thiết kế kiểm soát truy cập cho Khán giả, Ban tổ chức, Nhân sự soát vé. | E14: Role-permission matrix + enforcement tại endpoint/UI/app | F14: Nguyễn Bảo An | G14: Hoàn thành | H14: 100 | I14: blueprint/design.md — "Access Control Design" (4 role + 5 enforcement point) | J14: Đạt
A15: BP10 | B15: Blueprint | C15: Bắt buộc | D15: Giải pháp tải đột biến/rate limiting cho 80.000 người trong 5 phút, 70% ở phút đầu. | E15: Thuật toán, ngưỡng, key giới hạn, hành vi khi vượt ngưỡng | F15: Trương Nhật Đạt | G15: Hoàn thành | H15: 100 | I15: blueprint/design.md — Decision 7: token bucket rate limiting (ngưỡng, key, hành vi khi vượt) | J15: Đạt
A16: BP11 | B16: Blueprint | C16: Bắt buộc | D16: Circuit Breaker + Graceful Degradation khi VNPAY/MoMo lỗi. | E16: Closed/Open/Half-Open, threshold, fallback | F16: Trương Nhật Đạt | G16: Hoàn thành | H16: 100 | I16: blueprint/design.md — Decision 5: circuit breaker + graceful degradation | J16: Đạt
A17: BP12 | B17: Blueprint | C17: Bắt buộc | D17: Idempotency Key chống trừ tiền hai lần. | E17: Cách sinh/lưu/check key, TTL, response khi lặp | F17: Trương Nhật Đạt | G17: Hoàn thành | H17: 100 | I17: blueprint/design.md — Decision 4: idempotent payment lifecycle (key, TTL, response khi lặp) | J17: Đạt
... A23: IM03 | B23: Cài đặt | C23: Bắt buộc | D23: Enforce giới hạn vé/tài khoản trên toàn bộ đơn thành công, kể cả request đồng thời. | E23: Test concurrent + constraint/transaction/lock | F23: Trương Nhật Đạt | G23: Hoàn thành | H23: 100 | I23: packages/backend/src/ordering/infrastructure/database/prisma-inventory-reservation.repository.spec.ts — test "prevents concurrent same-user reservations from bypassing max per user after the row lock" (29/29 pass) | J23: Đạt
A24: IM04 | B24: Cài đặt | C24: Bắt buộc | D24: Thông báo app/email sau mua và nhắc trước 24 giờ; dễ thêm kênh mới. | E24: Code notification abstraction + scheduler/job + demo | F24: Nguyễn Lê Thế Vinh | G24: Hoàn thành | H24: 100 | I24: packages/backend/src/notification/ — concert-reminder.processor.ts, send-concert-reminders.use-case.ts; docs/manual-tests/concert-reminders.md | J24: Đạt | K24: Thêm kênh mới qua NotificationChannel port, không sửa logic mua vé.
A25: IM05 | B25: Cài đặt | C25: Bắt buộc | D25: Admin tạo/sửa/hủy concert, cấu hình loại vé và xem doanh thu/lượng bán. | E25: Demo role admin + API/UI + dữ liệu thống kê | F25: Phạm Quang Vinh | G25: Hoàn thành | H25: 100 | I25: apps/web/src/features/admin/ + apps/web/src/features/organizer/; packages/backend/src/concert-management/ | J25: Đạt
A26: IM06 | B26: Cài đặt | C26: Bắt buộc | D26: RBAC được cài thật ở API, trang admin và app soát vé. | E26: Middleware/policy + test quyền sai/đúng | F26: Nguyễn Bảo An | G26: Hoàn thành | H26: 100 | I26: packages/backend/src/identity/adapters/http/guards/roles.guard.ts + roles.guard.spec.ts (pass) | J26: Đạt
A27: IM07 | B27: Cài đặt | C27: Bắt buộc | D27: Mobile app quét QR và xác nhận vé tại cổng. | E27: Demo scan + validation + check-in record | F27: Nguyễn Lê Thế Vinh | G27: Hoàn thành | H27: 100 | I27: apps/checkin-mobile/src/features/scanner/ (ScannerScreen.tsx, QrCameraScanner.tsx); docs/manual-tests/checkin-mobile-app.md — 77/77 test pass | J27: Đạt
A28: IM08 | B28: Cài đặt | C28: Bắt buộc | D28: Soát vé offline, lưu tạm, đồng bộ khi có mạng, không mất dữ liệu/không vào hai lần. | E28: Demo bật/tắt mạng + sync/conflict test | F28: Nguyễn Lê Thế Vinh | G28: Hoàn thành | H28: 100 | I28: apps/checkin-mobile/src/features/offline-queue/; packages/backend/src/checkin/application/use-cases/batch-sync.use-case.ts + .spec.ts; docs/manual-tests/checkin-offline-sync.md | J28: Đạt
A29: IM09 | B29: Cài đặt | C29: Bắt buộc | D29: AI Artist Bio: upload PDF, tách/làm sạch text, gọi AI và tạo bio ngắn. | E29: PDF mẫu + pipeline + output + xử lý lỗi | F29: Nguyễn Lê Thế Vinh | G29: Hoàn thành | H29: 100 | I29: packages/backend/src/ai-artist-bio/ (gemini-artist-bio-generator.adapter.ts, simple-pdf-text-extractor.ts, artist-bio.processor.ts); apps/web/src/features/artist-bio/ArtistBioPanel.tsx; docs/manual-tests/ai-artist-bio.md | J29: Đạt
A30: IM10 | B30: Cài đặt | C30: Bắt buộc | D30: Định kỳ nhập Guest List CSV; xử lý file lỗi, trùng và không làm gián đoạn hệ thống. | E30: Job/scheduler + validation + duplicate report | F30: Nguyễn Lê Thế Vinh | G30: Hoàn thành | H30: 100 | I30: packages/backend/src/guest-list-import/ (guest-list-import.processor.ts, discover-guest-list-files.use-case.ts); apps/web/src/features/admin/guest-list/; test/guest-list/guest-list.e2e-spec.ts | J30: Đạt
A31: IM11 | B31: Cài đặt | C31: Bắt buộc | D31: Không oversell vé cuối cùng khi nhiều người mua đồng thời. | E31: Concurrency test + transaction/locking/atomic update | F31: Trương Nhật Đạt | G31: Hoàn thành | H31: 100 | I31: packages/backend/src/ordering/infrastructure/database/prisma-inventory-reservation.repository.ts (SELECT ... FOR UPDATE) + spec "prevents oversell when concurrent reservations serialize through the ticket type lock" | J31: Đạt
A32: IM12 | B32: Cài đặt | C32: Bắt buộc | D32: Cơ chế bảo vệ tải đột biến/rate limiting/bot-fairness cài trong code. | E32: Middleware/config + test vượt ngưỡng/load test | F32: Trương Nhật Đạt | G32: Hoàn thành | H32: 100 | I32: packages/backend/src/platform/rate-limiting/ (rate-limit.interceptor.ts, rate-limit-policy.ts, rate-limit-actor-key.service.ts) — 11/11 test pass | J32: Đạt
A33: IM13 | B33: Cài đặt | C33: Bắt buộc | D33: Circuit breaker và graceful degradation cài thật. | E33: Test payment lỗi liên tiếp; trang concert vẫn hoạt động | F33: Trương Nhật Đạt | G33: Hoàn thành | H33: 100 | I33: packages/backend/src/payment/infrastructure/redis/redis-payment-circuit-breaker.ts + .spec.ts (Closed/Open/Half-Open) | J33: Đạt
A34: IM14 | B34: Cài đặt | C34: Bắt buộc | D34: Idempotency cài thật, cùng request không tạo/trừ tiền hai lần. | E34: Test retry/same key/concurrent retry | F34: Trương Nhật Đạt | G34: Hoàn thành | H34: 100 | I34: packages/backend/src/payment/infrastructure/redis/redis-payment-idempotency.store.ts + .spec.ts | J34: Đạt
A35: IM15 | B35: Cài đặt | C35: Bắt buộc | D35: Caching cài thật, có TTL/invalidation phù hợp. | E35: Redis/cache code + hit/miss logs + consistency test | F35: Phạm Quang Vinh | G35: Hoàn thành | H35: 100 | I35: packages/backend/src/concert-management/application/cache/concert-cache-decorators.ts + .spec.ts (cache-aside, TTL, invalidation) | J35: Đạt
A36: IM16 | B36: Cài đặt | C36: Bắt buộc | D36: README đủ để clone và chạy không cần hỏi thêm. | E36: Prerequisites, env, commands, ports, accounts, troubleshooting | F36: Nguyễn Bảo An | G36: Hoàn thành | H36: 100 | I36: README.md (267 dòng: prerequisites, env, lệnh chạy, ports, tài khoản demo, troubleshooting) | J36: Đạt
... A38: IM18 | B38: Cài đặt | C38: Bắt buộc | D38: Toàn bộ hệ thống có thể khởi chạy và demo theo Blueprint. | E38: Script/docker compose + smoke test end-to-end | F38: Nguyễn Bảo An | G38: Hoàn thành | H38: 100 | I38: docker-compose.yml (postgres/redis/maildev) + npm run start:deps / dev:api / dev:worker / dev:web; README.md | J38: Đạt
A39: SB01 | B39: Nộp bài | C39: Bắt buộc | D39: Google Drive public và người chấm mở được bằng tài khoản khác/ẩn danh. | E39: Link Drive + ảnh kiểm tra quyền | G39: Chưa làm | H39: 0 | J39: Chưa kiểm tra | K39: Chưa tạo Google Drive nộp bài.
A40: SB02 | B40: Nộp bài | C40: Bắt buộc | D40: Drive có blueprint.pdf hoặc thư mục blueprint/ đầy đủ. | E40: Link trực tiếp tới Blueprint | G40: Chưa làm | H40: 0 | J40: Chưa kiểm tra | K40: Blueprint đã có trong repo (blueprint/design.md) nhưng chưa xuất PDF và đưa lên Drive.
A41: SB03 | B41: Nộp bài | C41: Bắt buộc | D41: Drive có src/, data/ và README.md. | E41: Link trực tiếp tới source + kiểm tra cấu trúc | G41: Chưa làm | H41: 0 | J41: Chưa kiểm tra | K41: Source + README đã có trong repo; chưa đóng gói src/ + data/ lên Drive.
A42: SB04 | B42: Nộp bài | C42: Bắt buộc | D42: Drive có clips/ video MP4 1080p, khoảng 720 kbps, camera + demo code/app. | E42: Link video + kiểm tra phát được | G42: Chưa làm | H42: 0 | J42: Chưa kiểm tra | K42: Chưa quay video demo (clips/).
A43: SB05 | B43: Nộp bài | C43: Bắt buộc | D43: File text tên mã-nhóm_mssv1_...txt; nội dung là link Drive public. | E43: Tên file và nội dung file text | G43: Chưa làm | H43: 0 | J43: Chưa kiểm tra | K43: Chưa tạo file text nộp LMS (cần mã nhóm + MSSV).

Sheet 03_PhanCongTask
A1: PHÂN CÔNG VÀ TỰ KHAI BÁO CÔNG VIỆC CÁ NHÂN
A3: Mỗi dòng là một task đủ cụ thể. Không ghi chung chung như “làm backend”. Ví dụ tốt: “Cài Idempotency-Key middleware, lưu key trong Redis TTL 24h và viết 5 test retry payment”.
A5: Task ID | B5: Requirement ID | C5: Nhóm nội dung | D5: Mô tả task cụ thể | E5: Sản phẩm/tiêu chí hoàn thành | F5: Người chính | G5: Người phối hợp | H5: Độ khó 1–5 | I5: Vai trò | J5: % HT | K5: Chất lượng 1–5 | L5: Link/ID minh chứng | M5: Giải thích đóng góp cá nhân | N5: Điểm công việc
A6: T01 | B6: BP01 | C6: Blueprint | D6: Viết Blueprint kiến trúc tổng thể TicketBox: chọn modular monolith NestJS, phân tầng clean/hexagonal, xác định failure boundary khi payment lỗi. | E6: blueprint/design.md có Context, Goals/Non-Goals và 12 Decisions; giải thích được phần nào vẫn chạy khi payment chết. | F6: Nguyễn Bảo An | G6: Phạm Quang Vinh | H6: 5 | I6: Chính | J6: 100 | K6: 5 | L6: openspec/changes/archive/2026-06-13-define-ticketbox-blueprint/; blueprint/design.md | M6: Tự dựng toàn bộ cấu trúc tài liệu kiến trúc và thống nhất ranh giới module cho cả nhóm. | N6: =IF(F6="","",H6*(J6/100)*(K6/5)*IF(I6="Chính",1.2,IF(I6="Phối hợp",1,0.7)))
A7: T02 | B7: BP02 | C7: Blueprint | D7: Vẽ C4 Level 1 (System Context) và Level 2 (Container): actor Khán giả/BTC/Soát vé và hệ thống ngoài VNPAY, MoMo, AI, CSV. | E7: blueprint/design.md có 2 mục C4 kèm sơ đồ mermaid và mô tả giao tiếp đồng bộ/bất đồng bộ. | F7: Nguyễn Bảo An | H7: 4 | I7: Chính | J7: 100 | K7: 5 | L7: blueprint/design.md — "C4 Level 1: System Context", "C4 Level 2: Container" | M7: Xác định ranh giới hệ thống và các container: api, worker, web, mobile, postgres, redis. | N7: =IF(F7="","",H7*(J7/100)*(K7/5)*IF(I7="Chính",1.2,IF(I7="Phối hợp",1,0.7)))
A8: T03 | B8: BP04 | C8: Blueprint | D8: Vẽ High-Level Architecture Flow, nhấn mạnh payment, AI, CSV, offline check-in và luồng phụ thuộc khi lỗi. | E8: Sơ đồ mermaid kèm mô tả failure boundary cho từng nhánh tích hợp. | F8: Nguyễn Bảo An | H8: 4 | I8: Chính | J8: 100 | K8: 5 | L8: blueprint/design.md — "High-Level Architecture Flow" | M8: Chỉ ra điểm hỏng và cơ chế suy giảm mềm cho từng tích hợp bên ngoài. | N8: =IF(F8="","",H8*(J8/100)*(K8/5)*IF(I8="Chính",1.2,IF(I8="Phối hợp",1,0.7)))
A9: T04 | B9: BP05 | C9: Blueprint | D9: Thiết kế mô hình dữ liệu: PostgreSQL là nguồn sự thật, Redis chỉ giữ state phái sinh; định nghĩa schema các entity chính. | E9: blueprint/design.md mục Database Design + prisma/schema.prisma; giải thích được consistency. | F9: Nguyễn Bảo An | G9: Phạm Quang Vinh | H9: 5 | I9: Chính | J9: 100 | K9: 5 | L9: blueprint/design.md — "Database Design"; prisma/schema.prisma | M9: Ra quyết định SQL/NoSQL (Decision 2) và thiết kế transaction boundary chống oversell. | N9: =IF(F9="","",H9*(J9/100)*(K9/5)*IF(I9="Chính",1.2,IF(I9="Phối hợp",1,0.7)))
A10: T05 | B10: BP09 | C10: Blueprint | D10: Thiết kế kiểm soát truy cập: ma trận 4 role (AUDIENCE, ORGANIZER, CHECKIN_STAFF, ADMIN) và 5 điểm enforcement. | E10: blueprint/design.md mục Access Control Design; nêu rõ frontend guard không phải nguồn sự thật. | F10: Nguyễn Bảo An | H10: 4 | I10: Chính | J10: 100 | K10: 5 | L10: blueprint/design.md — "Access Control Design" | M10: Định nghĩa role-permission và nguyên tắc server luôn xác thực lại mọi request. | N10: =IF(F10="","",H10*(J10/100)*(K10/5)*IF(I10="Chính",1.2,IF(I10="Phối hợp",1,0.7)))
A11: T06 | B11: BP14 | C11: Blueprint | D11: Viết 12 ADR/Decision cho các quyết định lớn và đánh đổi: SQL/NoSQL, JWT, broker, locking, cache, rate limit, AI provider. | E11: blueprint/design.md Decisions 1–12 và DECISIONS.md; mỗi quyết định có lý do và trade-off. | F11: Nguyễn Bảo An | H11: 4 | I11: Chính | J11: 100 | K11: 5 | L11: blueprint/design.md — Decisions 1–12; DECISIONS.md | M11: Ghi lại lập luận và đánh đổi để cả nhóm không phá vỡ pattern khi mở rộng. | N11: =IF(F11="","",H11*(J11/100)*(K11/5)*IF(I11="Chính",1.2,IF(I11="Phối hợp",1,0.7)))
A12: T07 | B12: BP15 | C12: Blueprint | D12: Thiết lập quy trình spec-driven OpenSpec: proposal.md + design.md + specs/[capability].md, quy ước 1 nhánh = 1 change = 1 PR. | E12: openspec/specs/ với hơn 70 capability và 92 change đã archive, mỗi change có acceptance criteria và error scenario. | F12: Nguyễn Bảo An | G12: Nguyễn Lê Thế Vinh | H12: 5 | I12: Chính | J12: 100 | K12: 5 | L12: blueprint/proposal.md; blueprint/specs/; docs/team-change-plan.md | M12: Thiết kế quy trình làm việc để 4 thành viên phát triển song song không giẫm chân nhau. | N12: =IF(F12="","",H12*(J12/100)*(K12/5)*IF(I12="Chính",1.2,IF(I12="Phối hợp",1,0.7)))
A13: T08 | B13: BP06 | C13: Blueprint | D13: Đặc tả luồng mua vé từ lúc bấm mua đến khi nhận e-ticket, gồm xử lý lỗi giữa chừng: hết vé, payment fail, hết hạn giữ chỗ. | E13: blueprint/design.md — Critical Business Flow "Ticket purchase from buy click to e-ticket". | F13: Nguyễn Bảo An | G13: Trương Nhật Đạt | H13: 4 | I13: Chính | J13: 100 | K13: 5 | L13: blueprint/design.md — "Ticket purchase from buy click to e-ticket" | M13: Mô tả từng bước và trạng thái đơn hàng khi lỗi xảy ra ở mỗi chặng. | N13: =IF(F13="","",H13*(J13/100)*(K13/5)*IF(I13="Chính",1.2,IF(I13="Phối hợp",1,0.7)))
A14: T09 | B14: IM06 | C14: Cài đặt | D14: Cài xác thực JWT và RBAC guard thật ở API: RolesGuard, decorator @Roles, kiểm tra ownership trong use-case. | E14: roles.guard.ts + roles.guard.spec.ts pass; nhân sự soát vé gọi API tạo concert bị chặn 403. | F14: Nguyễn Bảo An | G14: Phạm Quang Vinh | H14: 4 | I14: Chính | J14: 100 | K14: 5 | L14: openspec/changes/archive/2026-06-15-implement-auth-rbac/; packages/backend/src/identity/adapters/http/guards/roles.guard.ts | M14: Cài enforcement 3 lớp: guard ở controller, re-check ownership ở use-case, route guard ở frontend. | N14: =IF(F14="","",H14*(J14/100)*(K14/5)*IF(I14="Chính",1.2,IF(I14="Phối hợp",1,0.7)))
A15: T10 | B15: IM06 | C15: Cài đặt | D15: Cài quản trị người dùng và phân quyền admin: tạo/khóa tài khoản, gán role, gán staff theo concert. | E15: openspec change implement-admin-access-control; test/auth/admin-users.e2e-spec.ts pass. | F15: Nguyễn Bảo An | H15: 4 | I15: Chính | J15: 100 | K15: 4 | L15: openspec/changes/archive/2026-06-15-implement-admin-access-control/; test/auth/admin-users.e2e-spec.ts | M15: Xây lớp quản trị người dùng và ràng buộc staff chỉ soát vé concert được gán. | N15: =IF(F15="","",H15*(J15/100)*(K15/5)*IF(I15="Chính",1.2,IF(I15="Phối hợp",1,0.7)))
A16: T11 | B16: IM17 | C16: Cài đặt | D16: Viết migration Prisma và seed data: concert mẫu, loại vé, giá, sơ đồ chỗ ngồi và tài khoản demo cho 4 role. | E16: prisma/seed.ts chạy được; test/database/seed.spec.ts pass; npm run db:migrate && npm run db:seed. | F16: Nguyễn Bảo An | G16: Nguyễn Lê Thế Vinh | H16: 3 | I16: Chính | J16: 100 | K16: 5 | L16: openspec/changes/archive/2026-06-15-implement-database-migrations-and-seed/; prisma/seed.ts | M16: Dựng dữ liệu demo để cả nhóm và giảng viên chạy được hệ thống ngay sau khi clone. | N16: =IF(F16="","",H16*(J16/100)*(K16/5)*IF(I16="Chính",1.2,IF(I16="Phối hợp",1,0.7)))
A17: T12 | B17: IM18 | C17: Cài đặt | D17: Dựng platform foundation: docker-compose (postgres, redis, maildev), config service, health check và npm script khởi chạy. | E17: docker-compose.yml + npm run start:deps / dev:api / dev:worker; hệ thống khởi chạy end-to-end. | F17: Nguyễn Bảo An | G17: Nguyễn Lê Thế Vinh | H17: 4 | I17: Chính | J17: 100 | K17: 5 | L17: openspec/changes/archive/2026-06-15-implement-platform-foundation/; docker-compose.yml | M17: Chuẩn hóa môi trường chạy để máy mới clone về là chạy được, không cần hỏi thêm. | N17: =IF(F17="","",H17*(J17/100)*(K17/5)*IF(I17="Chính",1.2,IF(I17="Phối hợp",1,0.7)))
A18: T13 | B18: IM01 | C18: Cài đặt | D18: Xây audience-web foundation và trang khám phá: danh sách/chi tiết concert, tìm kiếm, lọc, hiển thị số vé còn lại. | E18: apps/audience-web/src/features/concerts/; số vé còn lại hiển thị đúng theo tồn kho. | F18: Nguyễn Bảo An | G18: Phạm Quang Vinh | H18: 4 | I18: Chính | J18: 100 | K18: 5 | L18: openspec/changes/archive/2026-06-24-establish-audience-web-foundation/; openspec/changes/archive/2026-06-24-implement-audience-discovery/ | M18: Dựng toàn bộ app khán giả bằng React/Vite và luồng khám phá sự kiện. | N18: =IF(F18="","",H18*(J18/100)*(K18/5)*IF(I18="Chính",1.2,IF(I18="Phối hợp",1,0.7)))
A19: T14 | B19: IM02 | C19: Cài đặt | D19: Xây trang tài khoản khán giả và ví vé: xem đơn hàng, vé đã mua, tải lại và gửi lại e-ticket QR. | E19: apps/audience-web: account, order history, ticket wallet; docs/frontend-ticket-qr-handoff.md. | F19: Nguyễn Bảo An | G19: Trương Nhật Đạt | H19: 4 | I19: Chính | J19: 100 | K19: 5 | L19: openspec/changes/archive/2026-06-24-implement-audience-account-and-tickets/ | M19: Hoàn thiện phần hậu mua vé để khán giả nhận và sử dụng được e-ticket. | N19: =IF(F19="","",H19*(J19/100)*(K19/5)*IF(I19="Chính",1.2,IF(I19="Phối hợp",1,0.7)))
A20: T15 | B20: IM16 | C20: Cài đặt | D20: Viết README đủ để clone và chạy: prerequisites, biến môi trường, lệnh chạy, ports, tài khoản demo, troubleshooting. | E20: README.md 267 dòng; máy mới làm theo README chạy được toàn hệ thống. | F20: Nguyễn Bảo An | G20: Nguyễn Lê Thế Vinh | H20: 2 | I20: Chính | J20: 100 | K20: 4 | L20: README.md | M20: Viết tài liệu khởi chạy để người chấm không phải hỏi thêm bất kỳ bước nào. | N20: =IF(F20="","",H20*(J20/100)*(K20/5)*IF(I20="Chính",1.2,IF(I20="Phối hợp",1,0.7)))
A21: T16 | B21: Mở rộng | C21: Cài đặt | D21: Ngoài yêu cầu: xây sàn bán lại vé (resale), P2P escrow, xử lý tranh chấp và tính năng tặng vé. | E21: openspec changes: official-resale-marketplace, resale-p2p-escrow, resale-platform, gift-ticket. | F21: Nguyễn Bảo An | H21: 5 | I21: Chính | J21: 100 | K21: 4 | L21: openspec/changes/archive/2026-07-05-official-resale-marketplace/; openspec/changes/archive/2026-07-05-resale-p2p-escrow/; openspec/changes/archive/2026-07-06-gift-ticket/ | M21: Mở rộng vượt yêu cầu: sàn giao dịch lại vé có escrow và cơ chế xử lý tranh chấp. | N21: =IF(F21="","",H21*(J21/100)*(K21/5)*IF(I21="Chính",1.2,IF(I21="Phối hợp",1,0.7)))
A22: T17 | B22: BP07 | C22: Blueprint | D22: Đặc tả luồng soát vé khi mất mạng và đồng bộ lại, chống vé vào hai lần khi hai thiết bị offline cùng quét một QR. | E22: blueprint/design.md — "Offline check-in and sync"; docs/manual-tests/checkin-offline-sync.md. | F22: Nguyễn Lê Thế Vinh | H22: 5 | I22: Chính | J22: 100 | K22: 5 | L22: blueprint/design.md — "Offline check-in and sync" | M22: Thiết kế conflict resolution: server là trọng tài, lần quét sau bị đánh dấu DUPLICATE. | N22: =IF(F22="","",H22*(J22/100)*(K22/5)*IF(I22="Chính",1.2,IF(I22="Phối hợp",1,0.7)))
A23: T18 | B23: BP08 | C23: Blueprint | D23: Đặc tả luồng nhập Guest List CSV: validate header và từng dòng, phát hiện trùng, import idempotent khi nhập lại. | E23: blueprint/design.md — "Guest list CSV import"; docs/manual-tests/guest-list-import.md. | F23: Nguyễn Lê Thế Vinh | G23: Trương Nhật Đạt | H23: 4 | I23: Chính | J23: 100 | K23: 5 | L23: blueprint/design.md — "Guest list CSV import" | M23: Thiết kế import idempotent để nhập lại cùng một file không tạo khách trùng. | N23: =IF(F23="","",H23*(J23/100)*(K23/5)*IF(I23="Chính",1.2,IF(I23="Phối hợp",1,0.7)))
A24: T19 | B24: IM07 | C24: Cài đặt | D24: Xây app soát vé React Native: đăng nhập staff, chọn concert và cổng, màn hình quét QR bằng camera thật. | E24: apps/checkin-mobile/src/features/scanner/ (ScannerScreen, QrCameraScanner); 77/77 test pass. | F24: Nguyễn Lê Thế Vinh | H24: 5 | I24: Chính | J24: 100 | K24: 5 | L24: openspec/changes/archive/2026-06-16-implement-checkin-mobile-app/; openspec/changes/archive/2026-06-24-add-camera-qr-scan/ | M24: Xây toàn bộ app mobile soát vé từ đầu, gồm quét QR bằng camera trên thiết bị thật. | N24: =IF(F24="","",H24*(J24/100)*(K24/5)*IF(I24="Chính",1.2,IF(I24="Phối hợp",1,0.7)))
A25: T20 | B25: IM08 | C25: Cài đặt | D25: Cài check-in API và batch sync: hash QR token, xác thực vé, ghi nhận check-in, chống double check-in. | E25: packages/backend/src/checkin/ + batch-sync.use-case.spec.ts pass; docs/manual-tests/checkin-api.md. | F25: Nguyễn Lê Thế Vinh | H25: 5 | I25: Chính | J25: 100 | K25: 5 | L25: openspec/changes/archive/2026-06-17-implement-checkin-api/; packages/backend/src/checkin/application/use-cases/batch-sync.use-case.ts | M25: Cài lớp server xác thực vé và giải quyết xung đột khi nhiều thiết bị cùng đồng bộ. | N25: =IF(F25="","",H25*(J25/100)*(K25/5)*IF(I25="Chính",1.2,IF(I25="Phối hợp",1,0.7)))
A26: T21 | B26: IM08 | C26: Cài đặt | D26: Cài soát vé offline: hàng đợi cục bộ, cache vé trên máy, đồng bộ khi có mạng, không mất dữ liệu. | E26: apps/checkin-mobile/src/features/offline-queue/ và ticket-cache/; test bật/tắt mạng pass. | F26: Nguyễn Lê Thế Vinh | H26: 5 | I26: Chính | J26: 100 | K26: 5 | L26: openspec/changes/archive/2026-06-23-implement-checkin-offline-sync/; openspec/changes/archive/2026-06-24-offline-ticket-cache-sync/ | M26: Cài offline queue và cơ chế sync có xử lý xung đột, đúng theo thiết kế BP07. | N26: =IF(F26="","",H26*(J26/100)*(K26/5)*IF(I26="Chính",1.2,IF(I26="Phối hợp",1,0.7)))
A27: T22 | B27: IM04 | C27: Cài đặt | D27: Xây module notification: abstraction đa kênh (in-app, email), queue BullMQ, retry/backoff và dedupe key. | E27: packages/backend/src/notification/; thêm kênh mới không phải sửa logic mua vé. | F27: Nguyễn Lê Thế Vinh | G27: Nguyễn Bảo An | H27: 4 | I27: Chính | J27: 100 | K27: 5 | L27: openspec/changes/archive/2026-06-16-implement-notification-delivery/; packages/backend/src/notification/ | M27: Thiết kế port đa kênh để mở rộng (ví dụ Zalo OA) mà không đụng vào nghiệp vụ mua vé. | N27: =IF(F27="","",H27*(J27/100)*(K27/5)*IF(I27="Chính",1.2,IF(I27="Phối hợp",1,0.7)))
A28: T23 | B28: IM04 | C28: Cài đặt | D28: Cài nhắc lịch trước 24 giờ bằng worker quét định kỳ, gửi email SMTP thật và thông báo realtime qua SSE. | E28: concert-reminder.processor.ts + send-concert-reminders.use-case.ts; docs/manual-tests/concert-reminders.md. | F28: Nguyễn Lê Thế Vinh | H28: 4 | I28: Chính | J28: 100 | K28: 5 | L28: openspec/changes/archive/2026-06-23-implement-concert-reminders/; openspec/changes/archive/2026-06-24-enable-authenticated-smtp-email/ | M28: Cài job nhắc lịch idempotent (không gửi trùng) và kênh thông báo realtime SSE. | N28: =IF(F28="","",H28*(J28/100)*(K28/5)*IF(I28="Chính",1.2,IF(I28="Phối hợp",1,0.7)))
A29: T24 | B29: IM09 | C29: Cài đặt | D29: Xây pipeline AI Artist Bio: upload PDF press kit, validate, trích và làm sạch text, gọi Gemini, fallback cục bộ, retry khi lỗi. | E29: packages/backend/src/ai-artist-bio/ (pdf-validation, pdf text extractor, gemini adapter, processor); 12 file test pass. | F29: Nguyễn Lê Thế Vinh | G29: Phạm Quang Vinh | H29: 5 | I29: Chính | J29: 100 | K29: 5 | L29: openspec/changes/archive/2026-06-18-implement-ai-artist-bio/; packages/backend/src/ai-artist-bio/ | M29: Xây toàn bộ pipeline PDF sang bio, gồm xử lý PDF lỗi và provider fallback khi AI chết. | N29: =IF(F29="","",H29*(J29/100)*(K29/5)*IF(I29="Chính",1.2,IF(I29="Phối hợp",1,0.7)))
A30: T25 | B30: IM10 | C30: Cài đặt | D30: Xây import Guest List CSV: worker quét file định kỳ, validate header và dòng, phát hiện trùng, báo cáo lỗi, import idempotent. | E30: packages/backend/src/guest-list-import/; test/guest-list/guest-list.e2e-spec.ts pass. | F30: Nguyễn Lê Thế Vinh | G30: Trương Nhật Đạt | H30: 5 | I30: Chính | J30: 100 | K30: 5 | L30: openspec/changes/archive/2026-06-21-implement-guest-list-import/; packages/backend/src/guest-list-import/ | M30: Cài job import chịu lỗi: file hỏng không làm sập hệ thống, nhập lại không tạo khách trùng. | N30: =IF(F30="","",H30*(J30/100)*(K30/5)*IF(I30="Chính",1.2,IF(I30="Phối hợp",1,0.7)))
A31: T26 | B31: IM01 | C31: Cài đặt | D31: Thiết lập package @ticketbox/api-types: contract Zod dùng chung giữa backend, web và mobile. | E31: packages/api-types/; client parse response bằng đúng schema backend dùng. | F31: Nguyễn Lê Thế Vinh | G31: Nguyễn Bảo An | H31: 4 | I31: Chính | J31: 100 | K31: 5 | L31: openspec/changes/archive/2026-06-20-establish-shared-api-types/; packages/api-types/ | M31: Chuẩn hóa wire contract một nguồn duy nhất, tránh lệch kiểu giữa backend và frontend. | N31: =IF(F31="","",H31*(J31/100)*(K31/5)*IF(I31="Chính",1.2,IF(I31="Phối hợp",1,0.7)))
A32: T27 | B32: IM17 | C32: Cài đặt | D32: Mở rộng seed data demo: thêm concert, loại vé, sơ đồ khu và tài khoản demo đủ 4 role. | E32: openspec change expand-demo-seed-data; prisma/seed.ts. | F32: Nguyễn Lê Thế Vinh | G32: Nguyễn Bảo An | H32: 2 | I32: Phối hợp | J32: 100 | K32: 4 | L32: openspec/changes/archive/2026-06-27-expand-demo-seed-data/ | M32: Bổ sung dữ liệu demo phong phú để quay video và phục vụ vấn đáp. | N32: =IF(F32="","",H32*(J32/100)*(K32/5)*IF(I32="Chính",1.2,IF(I32="Phối hợp",1,0.7)))
A33: T28 | B33: KT | C33: Kiểm thử | D33: Viết tài liệu manual test cho các luồng khó: offline sync, guest list, AI bio, reminders, waiting room, lottery. | E33: docs/manual-tests/ gồm 12 file kịch bản kiểm thử tay tái hiện được. | F33: Nguyễn Lê Thế Vinh | G33: Trương Nhật Đạt | H33: 3 | I33: Chính | J33: 100 | K33: 4 | L33: docs/manual-tests/ | M33: Chuẩn hóa kịch bản kiểm thử tay để cả nhóm và giảng viên tái hiện được lỗi. | N33: =IF(F33="","",H33*(J33/100)*(K33/5)*IF(I33="Chính",1.2,IF(I33="Phối hợp",1,0.7)))
A34: T29 | B34: Mở rộng | C34: Cài đặt | D34: Ngoài yêu cầu: Official Waitlist (báo khi có vé), Presale Lottery (bốc thăm) và Virtual Waiting Room (phòng chờ ảo). | E34: 3 openspec change kèm refactor về mô hình public-pool; toàn bộ test liên quan pass. | F34: Nguyễn Lê Thế Vinh | H34: 5 | I34: Chính | J34: 100 | K34: 5 | L34: openspec/changes/archive/2026-07-08-add-official-waitlist/; openspec/changes/archive/2026-07-09-add-presale-lottery/; openspec/changes/archive/2026-07-10-add-virtual-waiting-room/ | M34: Mở rộng vượt yêu cầu: 3 cơ chế xử lý tình huống cầu vượt cung khi bán vé hot. | N34: =IF(F34="","",H34*(J34/100)*(K34/5)*IF(I34="Chính",1.2,IF(I34="Phối hợp",1,0.7)))
A35: T30 | B35: BP13 | C35: Blueprint | D35: Thiết kế chiến lược caching: cache-aside, TTL khác nhau cho danh sách và chi tiết concert, invalidation khi bán vé. | E35: blueprint/design.md — Decision 6; nêu rõ TTL từng loại và thời điểm invalidate. | F35: Phạm Quang Vinh | G35: Trương Nhật Đạt | H35: 4 | I35: Chính | J35: 100 | K35: 5 | L35: blueprint/design.md — Decision 6: cache-aside with active invalidation | M35: Chọn cache-aside kèm active invalidation và định TTL ngắn cho dữ liệu vé vì dễ lệch. | N35: =IF(F35="","",H35*(J35/100)*(K35/5)*IF(I35="Chính",1.2,IF(I35="Phối hợp",1,0.7)))
A36: T31 | B36: IM01 | C36: Cài đặt | D36: Xây concert catalog backend: API danh sách và chi tiết concert, nghệ sĩ, địa điểm và số vé còn lại. | E36: packages/backend/src/concert-management/; test/concert-catalog/concert-catalog.e2e-spec.ts pass. | F36: Phạm Quang Vinh | G36: Nguyễn Bảo An | H36: 4 | I36: Chính | J36: 100 | K36: 5 | L36: openspec/changes/archive/2026-06-16-implement-concert-catalog/; packages/backend/src/concert-management/ | M36: Xây module catalog và API công khai làm nền cho toàn bộ trang khán giả. | N36: =IF(F36="","",H36*(J36/100)*(K36/5)*IF(I36="Chính",1.2,IF(I36="Phối hợp",1,0.7)))
A37: T32 | B37: IM15 | C37: Cài đặt | D37: Cài caching thật bằng Redis: decorator cache-aside cho catalog, TTL theo loại dữ liệu, invalidate khi có thay đổi. | E37: concert-cache-decorators.ts + .spec.ts pass; có log hit/miss và test consistency. | F37: Phạm Quang Vinh | G37: Trương Nhật Đạt | H37: 5 | I37: Chính | J37: 100 | K37: 5 | L37: openspec/changes/archive/2026-06-21-implement-concert-caching/; packages/backend/src/concert-management/application/cache/concert-cache-decorators.ts | M37: Cài cache-aside có invalidation chủ động, tránh hiển thị sai số vé còn lại. | N37: =IF(F37="","",H37*(J37/100)*(K37/5)*IF(I37="Chính",1.2,IF(I37="Phối hợp",1,0.7)))
A38: T33 | B38: IM05 | C38: Cài đặt | D38: Xây quản trị concert cho ban tổ chức: tạo, sửa, hủy concert, cấu hình loại vé và giá, xem doanh thu và lượng bán. | E38: concert-management backend + apps/web admin/organizer; test/concert-admin e2e pass. | F38: Phạm Quang Vinh | G38: Nguyễn Bảo An | H38: 5 | I38: Chính | J38: 100 | K38: 5 | L38: openspec/changes/archive/2026-06-16-implement-concert-admin-management/; openspec/changes/archive/2026-06-20-implement-web-concert-management/ | M38: Xây toàn bộ CRUD concert và dashboard doanh thu cho ban tổ chức. | N38: =IF(F38="","",H38*(J38/100)*(K38/5)*IF(I38="Chính",1.2,IF(I38="Phối hợp",1,0.7)))
A39: T34 | B39: IM05 | C39: Cài đặt | D39: Tách quyền admin và organizer trên web, làm dashboard đăng nhập và điều hướng theo role. | E39: apps/web/src/features/admin/ và organizer/; route guard theo role hoạt động đúng. | F39: Phạm Quang Vinh | G39: Nguyễn Bảo An | H39: 4 | I39: Chính | J39: 100 | K39: 5 | L39: openspec/changes/archive/2026-06-24-separate-admin-organizer-features/; openspec/changes/archive/2026-06-20-implement-web-login-and-organizer-dashboard/ | M39: Phân tách rõ màn hình admin và organizer, khớp với ma trận RBAC đã thiết kế. | N39: =IF(F39="","",H39*(J39/100)*(K39/5)*IF(I39="Chính",1.2,IF(I39="Phối hợp",1,0.7)))
A40: T35 | B40: IM01 | C40: Cài đặt | D40: Cài sơ đồ chỗ ngồi SVG theo khu: upload seating map, ánh xạ khu với loại vé, render và làm cứng luồng SVG. | E40: apps/audience-web SeatingZoneMap.tsx + backend seating zone assets; openspec harden-seating-zone-svg-flow. | F40: Phạm Quang Vinh | G40: Nguyễn Bảo An | H40: 5 | I40: Chính | J40: 100 | K40: 5 | L40: openspec/changes/archive/2026-06-19-implement-seating-map-assets/; openspec/changes/archive/2026-06-24-harden-seating-zone-svg-flow/ | M40: Xây tính năng sơ đồ khu bằng SVG và làm cứng luồng upload chống SVG độc hại. | N40: =IF(F40="","",H40*(J40/100)*(K40/5)*IF(I40="Chính",1.2,IF(I40="Phối hợp",1,0.7)))
A41: T36 | B41: IM05 | C41: Cài đặt | D41: Cài cloud object storage và upload poster/asset concert, phục vụ file tĩnh, xóa asset cũ. | E41: storage adapter trong platform; openspec cloud-object-storage và concert-poster-upload. | F41: Phạm Quang Vinh | H41: 4 | I41: Chính | J41: 100 | K41: 4 | L41: openspec/changes/archive/2026-06-19-implement-cloud-object-storage/; openspec/changes/archive/2026-06-20-implement-concert-poster-upload/ | M41: Trừu tượng hóa lưu trữ file (poster, seating map, PDF, CSV) qua một port duy nhất. | N41: =IF(F41="","",H41*(J41/100)*(K41/5)*IF(I41="Chính",1.2,IF(I41="Phối hợp",1,0.7)))
A42: T37 | B42: IM05 | C42: Cài đặt | D42: Xây trình sửa sơ đồ khu và ánh xạ loại vé (venue map zone editor) cùng quản lý địa điểm concert. | E42: openspec venue-map-zone-ticket-editor và add-concert-location-management. | F42: Phạm Quang Vinh | H42: 4 | I42: Chính | J42: 100 | K42: 4 | L42: openspec/changes/archive/2026-06-24-venue-map-zone-ticket-editor/; openspec/changes/archive/2026-07-05-add-concert-location-management/ | M42: Cho ban tổ chức tự cấu hình khu ngồi và địa điểm mà không cần sửa code. | N42: =IF(F42="","",H42*(J42/100)*(K42/5)*IF(I42="Chính",1.2,IF(I42="Phối hợp",1,0.7)))
...

Sheet 04_TuDanhGia
A1: TỰ ĐÁNH GIÁ CÁ NHÂN — MỖI THÀNH VIÊN MỘT DÒNG
A3: Thang 1–5: 1 = gần như chưa tham gia/không giải thích được; 3 = hoàn thành phần được giao; 5 = chủ động, có minh chứng rõ và giải thích được quyết định kỹ thuật khi vấn đáp.
A5: STT | B5: Thành viên | C5: Hiểu bài toán | D5: Blueprint/kiến trúc | E5: Cài đặt nghiệp vụ | F5: Cơ chế kỹ thuật | G5: Kiểm thử/chất lượng | H5: Tài liệu/README | I5: Demo/video | J5: Hợp tác nhóm | K5: Khả năng vấn đáp | L5: Điểm TB | M5: 3 đóng góp quan trọng nhất | N5: Phần chưa hoàn thành/hạn chế | O5: Minh chứng tiêu biểu | P5: Tỷ lệ đóng góp tự khai (%) | Q5: Cam kết trung thực
A6: 1 | B6: =IF('01_ThongTinNhom'!B16="","",'01_ThongTinNhom'!B16) | C6: 5 | D6: 5 | E6: 5 | F6: 5 | G6: 5 | H6: 5 | I6: 4 | J6: 5 | K6: 5 | L6: =IF(B6="","",AVERAGE(C6:K6)) | M6: (1) Viết toàn bộ Blueprint: kiến trúc modular monolith + clean/hexagonal, C4 L1/L2, ERD, 12 ADR. (2) Cài xác thực JWT và RBAC guard 3 lớp (RolesGuard + re-check ownership trong use-case). (3) Dựng platform foundation (docker-compose, config, health) + migration/seed và app khán giả audience-web. | N6: Chưa trực tiếp cài các cơ chế payment (circuit breaker, idempotency, rate limiting) — phần này do Nhật Đạt làm, tôi chỉ review thiết kế. Chưa quay video demo. | O6: MC01 (blueprint/design.md), MC16 (PR #3 RBAC), MC19 (PR #1 platform foundation), MC24 (README.md) | P6: 27 | Q6: Có
A7: 2 | B7: =IF('01_ThongTinNhom'!B17="","",'01_ThongTinNhom'!B17) | C7: 5 | D7: 4 | E7: 5 | F7: 5 | G7: 5 | H7: 5 | I7: 5 | J7: 5 | K7: 5 | L7: =IF(B7="","",AVERAGE(C7:K7)) | M7: (1) Xây concert catalog backend và toàn bộ trang quản trị cho ban tổ chức (CRUD concert, loại vé, dashboard doanh thu). (2) Cài caching Redis cache-aside: availability TTL 5s, detail TTL 300s, invalidate theo prefix khi ghi. (3) Cài sơ đồ chỗ ngồi SVG theo khu, object storage, upload poster và trình sửa venue map. | N7: Mảng cơ chế nền (oversell, payment) không phải phần tôi làm nên chỉ nắm ở mức thiết kế. Blueprint tôi chỉ đóng góp Decision 6 (caching). | O7: MC58 (PR #5 catalog), MC61 (commit 4160a4c caching), MC59 (PR #6 quản trị concert), MC65 (test UI 39/39 pass) | P7: 21 | Q7: Có
A8: 3 | B8: =IF('01_ThongTinNhom'!B18="","",'01_ThongTinNhom'!B18) | C8: 5 | D8: 5 | E8: 5 | F8: 5 | G8: 5 | H8: 5 | I8: 4 | J8: 5 | K8: 5 | L8: =IF(B8="","",AVERAGE(C8:K8)) | M8: (1) Xây app soát vé React Native và toàn bộ luồng offline: hàng đợi cục bộ, ticket cache, batch-sync có xử lý xung đột (cùng máy = DUPLICATE, máy khác = CONFLICT). (2) Xây pipeline AI Artist Bio (validate chữ ký %PDF-, trích text, gọi Gemini, fallback cục bộ, retry backoff) và import Guest List CSV idempotent (checksum sha256 + chuẩn hóa email). (3) Xây module notification đa kênh qua NotificationChannelPort + nhắc lịch trước 24 giờ. | N8: Không tham gia sâu mảng payment và chống oversell. Blueprint tôi chỉ viết 2 luồng nghiệp vụ (BP07 offline check-in, BP08 CSV). | O8: MC41 (PR #10 mobile), MC44 (PR #25 offline sync), MC49 (PR #13 AI bio), MC51 (PR #20 CSV import) | P8: 24 | Q8: Có
A9: 4 | B9: =IF('01_ThongTinNhom'!B19="","",'01_ThongTinNhom'!B19) | C9: 5 | D9: 5 | E9: 5 | F9: 5 | G9: 5 | H9: 4 | I9: 5 | J9: 5 | K9: 5 | L9: =IF(B9="","",AVERAGE(C9:K9)) | M9: (1) Cài cơ chế chống oversell: SELECT ... FOR UPDATE khóa dòng ticket_type trong transaction đặt chỗ, có test chứng minh 2 người mua vé cuối cùng chỉ 1 người thắng. (2) Cài giới hạn vé/tài khoản chống lách khi request đồng thời (đếm cả đơn PENDING sau row lock) — 29/29 test pass. (3) Cài payment resilience: idempotency (Redis SET NX, phát hiện MISMATCH), circuit breaker (3 lỗi → OPEN, cooldown 30s) và rate limiting token bucket 7 policy. | N9: Phần frontend admin và blueprint tổng thể không phải mảng của tôi. Tài liệu tôi viết chủ yếu là Decision 4/5/7 và docs kỹ thuật. | O9: MC27 (commit 512d263 oversell), MC29 (test 29/29 giới hạn vé), MC31 (commit 69b610c circuit breaker), MC32 (commit 19ead99 rate limit) | P9: 28 | Q9: Có

Sheet 05_DanhGiaCheo
A1: ĐÁNH GIÁ CHÉO GIỮA CÁC THÀNH VIÊN
A3: Mỗi thành viên đánh giá các thành viên còn lại, không tự đánh giá chính mình. Nhóm 1 thành viên để trống. Nhận xét phải có ví dụ cụ thể, tránh tất cả đều 5 điểm.
A5: STT | B5: Người đánh giá | C5: Người được đánh giá | D5: Mức đóng góp | E5: Đúng tiến độ | F5: Chất lượng đầu ra | G5: Chủ động xử lý vấn đề | H5: Hỗ trợ nhóm | I5: Khả năng giải thích phần việc | J5: Điểm TB | K5: Nhận xét cụ thể | L5: Ví dụ/minh chứng | M5: Xác nhận
A6: 1 | B6: Nguyễn Bảo An | C6: Phạm Quang Vinh | D6: 5 | E6: 5 | F6: 5 | G6: 5 | H6: 5 | I6: 5 | J6: =IF(C6="","",AVERAGE(D6:I6)) | K6: Chủ lực mảng quản trị và catalog. Cache-aside làm rất chắc: tách TTL 5s cho số vé còn lại và 300s cho thông tin concert, có invalidation theo prefix nên không bị hiển thị sai tồn kho. Chủ động nhận làm hộ UI cho AI bio khi Thế Vinh đang bận backend. | L6: PR #5, #6, #17; commit 4160a4c (caching); apps/web/src/features/artist-bio/ArtistBioPanel.tsx | M6: Có
A7: 2 | B7: Nguyễn Bảo An | C7: Nguyễn Lê Thế Vinh | D7: 5 | E7: 5 | F7: 5 | G7: 5 | H7: 5 | I7: 5 | J7: =IF(C7="","",AVERAGE(D7:I7)) | K7: Ôm nhiều module khó nhất và đều hoàn thành: mobile check-in, offline sync, AI bio, CSV import, notification. Xử lý xung đột offline rất bài bản — server làm trọng tài, phân biệt rõ DUPLICATE và CONFLICT. Viết 12 tài liệu manual test giúp cả nhóm tái hiện lỗi. | L7: PR #10, #12, #25, #13, #20; docs/manual-tests/ (12 file); batch-sync.use-case.spec.ts pass | M7: Có
A8: 3 | B8: Nguyễn Bảo An | C8: Trương Nhật Đạt | D8: 5 | E8: 5 | F8: 5 | G8: 5 | H8: 5 | I8: 5 | J8: =IF(C8="","",AVERAGE(D8:I8)) | K8: Nắm chắc phần khó nhất của đề: chống oversell và payment resilience. Không chỉ code mà còn viết test đồng thời chứng minh — đây là thứ thầy chắc chắn hỏi. Ngưỡng rate limit tách theo 7 policy chứ không dùng một ngưỡng chung, cho thấy hiểu bài toán tải đột biến. | L8: commit 512d263, d3e504b, 69b610c, 19ead99; test 29/29 pass (oversell + giới hạn vé đồng thời) | M8: Có
A9: 4 | B9: Phạm Quang Vinh | C9: Nguyễn Bảo An | D9: 5 | E9: 5 | F9: 5 | G9: 5 | H9: 5 | I9: 5 | J9: =IF(C9="","",AVERAGE(D9:I9)) | K9: Người dựng nền cho cả nhóm: Blueprint, quy trình OpenSpec (92 change), platform foundation, RBAC. Nhờ có contract và ranh giới module rõ ràng nên 4 người làm song song không giẫm chân nhau. Giải thích được mọi quyết định kiến trúc. | L9: blueprint/design.md (Decisions 1–12); PR #1, #2, #3; openspec/changes/archive/ (92 change) | M9: Có
A10: 5 | B10: Phạm Quang Vinh | C10: Nguyễn Lê Thế Vinh | D10: 5 | E10: 5 | F10: 5 | G10: 5 | H10: 5 | I10: 5 | J10: =IF(C10="","",AVERAGE(D10:I10)) | K10: Khối lượng lớn nhất nhóm và chất lượng đồng đều. Pipeline AI bio thiết kế phòng thủ tốt: validate cả chữ ký nhị phân %PDF-, có fallback cục bộ nên AI chết hệ thống vẫn chạy, và bắt buộc người duyệt trước khi công khai bio. | L10: PR #13 (AI bio); packages/backend/src/ai-artist-bio/ (12 file test pass) | M10: Có
A11: 6 | B11: Phạm Quang Vinh | C11: Trương Nhật Đạt | D11: 5 | E11: 4 | F11: 5 | G11: 5 | H11: 5 | I11: 5 | J11: =IF(C11="","",AVERAGE(D11:I11)) | K11: Mảng payment và tồn kho làm rất kỹ. Idempotency xử lý được cả ca khó là cùng key nhưng khác payload (trả MISMATCH thay vì ghi đè). Đôi lúc merge thẳng vào dev không qua PR nên khó review, nhưng chất lượng code và test thì không có gì phải bàn. | L11: commit d3e504b (idempotency store); redis-payment-circuit-breaker.spec.ts pass | M11: Có
A12: 7 | B12: Nguyễn Lê Thế Vinh | C12: Nguyễn Bảo An | D12: 5 | E12: 5 | F12: 5 | G12: 5 | H12: 5 | I12: 5 | J12: =IF(C12="","",AVERAGE(D12:I12)) | K12: Kiến trúc và quy trình do bạn đặt ra là lý do nhóm chạy được 92 change trong 5 tuần mà không vỡ. Phần RBAC cài đúng 3 lớp, tôi thử gọi API bằng token staff thì bị chặn ngay ở guard, đúng như thiết kế. | L12: blueprint/design.md — Access Control Design; roles.guard.ts + roles.guard.spec.ts | M12: Có
A13: 8 | B13: Nguyễn Lê Thế Vinh | C13: Phạm Quang Vinh | D13: 5 | E13: 5 | F13: 5 | G13: 5 | H13: 5 | I13: 4 | J13: =IF(C13="","",AVERAGE(D13:I13)) | K13: Làm nhanh và ổn định mảng admin/catalog. Đặc biệt đánh giá cao việc bạn nhận làm hộ phần UI AI Artist Bio cho tôi khi tôi còn kẹt ở backend — đúng tinh thần hỗ trợ nhóm. Mảng cơ chế nền (oversell, payment) bạn nắm chưa sâu bằng. | L13: apps/web/src/features/artist-bio/; PR #15 (seating map SVG); PR #46 (bulk staff + PDF) | M13: Có
A14: 9 | B14: Nguyễn Lê Thế Vinh | C14: Trương Nhật Đạt | D14: 5 | E14: 5 | F14: 5 | G14: 5 | H14: 5 | I14: 5 | J14: =IF(C14="","",AVERAGE(D14:I14)) | K14: Xử lý bài toán tranh chấp vé và trừ tiền hai lần rất chuẩn, có test đồng thời làm bằng chứng chứ không nói suông. Bạn cũng hỗ trợ tôi làm UI admin cho Guest List. Tài liệu bạn viết hơi ít so với lượng code. | L14: prisma-inventory-reservation.repository.spec.ts (29/29 pass); openspec 2026-07-14-integrate-guest-list-ui | M14: Có
A15: 10 | B15: Trương Nhật Đạt | C15: Nguyễn Bảo An | D15: 5 | E15: 5 | F15: 5 | G15: 5 | H15: 5 | I15: 5 | J15: =IF(C15="","",AVERAGE(D15:I15)) | K15: Thiết kế transaction boundary trong Blueprint chính là cơ sở để tôi cài chống oversell. Bạn review kỹ và bắt được vài lỗ hổng trong luồng giữ chỗ trước khi tôi merge. Nắm toàn bộ hệ thống, hỏi gì cũng trả lời được. | L15: blueprint/design.md — Database Design; PR #1, #2, #3 | M15: Có
A16: 11 | B16: Trương Nhật Đạt | C16: Phạm Quang Vinh | D16: 5 | E16: 5 | F16: 5 | G16: 5 | H16: 5 | I16: 5 | J16: =IF(C16="","",AVERAGE(D16:I16)) | K16: Cache của bạn phối hợp tốt với phần đặt chỗ của tôi: TTL 5s cho số vé còn lại nên UI không lệch nhiều, mà vẫn không ảnh hưởng tới tính đúng đắn vì nguồn sự thật là transaction có row lock. Phần admin/organizer làm đầy đủ và gọn. | L16: commit 4160a4c; caching-get-concert-availability.use-case.ts (TTL 5s) | M16: Có
A17: 12 | B17: Trương Nhật Đạt | C17: Nguyễn Lê Thế Vinh | D17: 5 | E17: 5 | F17: 5 | G17: 5 | H17: 5 | I17: 5 | J17: =IF(C17="","",AVERAGE(D17:I17)) | K17: Ôm nhiều mảng nhất mà vẫn về đích: mobile, offline sync, AI, CSV, notification. Cách bạn chống trùng khi import CSV (checksum sha256 cho file + chuẩn hóa email cho từng dòng) là giải pháp tôi thấy sạch nhất trong nhóm. | L17: PR #20 (CSV import); claim-guest-list-import.use-case.ts; domain/normalization.ts | M17: Có
A18: 13 | J18: =IF(C18="","",AVERAGE(D18:I18))
A19: 14 | J19: =IF(C19="","",AVERAGE(D19:I19))
A20: 15 | J20: =IF(C20="","",AVERAGE(D20:I20))
A21: 16 | J21: =IF(C21="","",AVERAGE(D21:I21))
A22: 17 | J22: =IF(C22="","",AVERAGE(D22:I22))
A23: 18 | J23: =IF(C23="","",AVERAGE(D23:I23))
A24: 19 | J24: =IF(C24="","",AVERAGE(D24:I24))
A25: 20 | J25: =IF(C25="","",AVERAGE(D25:I25))
A26: 21 | J26: =IF(C26="","",AVERAGE(D26:I26))
A27: 22 | J27: =IF(C27="","",AVERAGE(D27:I27))
A28: 23 | J28: =IF(C28="","",AVERAGE(D28:I28))
A29: 24 | J29: =IF(C29="","",AVERAGE(D29:I29))

Sheet 06_MinhChung_NopBai
A1: DANH MỤC MINH CHỨNG VÀ KIỂM TRA GOOGLE DRIVE
A3: A. DANH MỤC MINH CHỨNG
A5: ID | B5: Loại | C5: Requirement ID | D5: Thành viên | E5: Mô tả minh chứng | F5: URL/Path | G5: Ngày | H5: Cách kiểm tra | I5: Kết quả | J5: Ghi chú
A6: MC01 | B6: Tài liệu | C6: BP01 | D6: Nguyễn Bảo An | E6: Blueprint kiến trúc tổng thể: modular monolith NestJS, clean/hexagonal, failure boundary. | F6: blueprint/design.md (commit 765d282) | G6: 2026-06-13 | H6: Mở blueprint/design.md, đọc mục Context và Decisions 1–12. | I6: Đạt
A7: MC02 | B7: Sơ đồ | C7: BP02 | D7: Nguyễn Bảo An | E7: Sơ đồ C4 Level 1 — System Context: actor và hệ thống ngoài (VNPAY/MoMo, AI, CSV). | F7: blueprint/design.md — "C4 Level 1: System Context" | G7: 2026-06-13 | H7: Mở design.md, tìm mục C4 Level 1; sơ đồ mermaid render được trên GitHub. | I7: Đạt
A8: MC03 | B8: Sơ đồ | C8: BP03 | D8: Nguyễn Bảo An | E8: Sơ đồ C4 Level 2 — Container: api, worker, web, audience-web, mobile, Postgres, Redis. | F8: blueprint/design.md — "C4 Level 2: Container" | G8: 2026-06-13 | H8: Đối chiếu sơ đồ với docker-compose.yml và thư mục apps/. | I8: Đạt
A9: MC04 | B9: Sơ đồ | C9: BP04 | D9: Nguyễn Bảo An | E9: High-Level Architecture Flow: luồng dữ liệu và ranh giới lỗi cho payment, AI, CSV, offline check-in. | F9: blueprint/design.md — "High-Level Architecture Flow" | G9: 2026-06-13 | H9: Mở design.md mục High-Level Architecture Flow. | I9: Đạt
A10: MC05 | B10: Tài liệu | C10: BP05 | D10: Nguyễn Bảo An | E10: Thiết kế dữ liệu: chọn PostgreSQL làm nguồn sự thật, Redis chỉ giữ state phái sinh; schema entity chính. | F10: blueprint/design.md — "Database Design"; prisma/schema.prisma | G10: 2026-06-13 | H10: Đối chiếu mục Database Design với prisma/schema.prisma. | I10: Đạt
A11: MC06 | B11: Tài liệu | C11: BP06 | D11: Nguyễn Bảo An | E11: Đặc tả luồng mua vé từ bấm mua đến nhận e-ticket, gồm xử lý lỗi giữa chừng. | F11: blueprint/design.md — "Ticket purchase from buy click to e-ticket" | G11: 2026-06-13 | H11: Đọc mục Critical Business Flows trong design.md. | I11: Đạt
A12: MC07 | B12: Tài liệu | C12: BP07 | D12: Nguyễn Lê Thế Vinh | E12: Đặc tả luồng soát vé offline và đồng bộ, chống vé vào hai lần. | F12: blueprint/design.md — "Offline check-in and sync"; docs/manual-tests/checkin-offline-sync.md | G12: 2026-06-23 | H12: Đọc design.md rồi chạy kịch bản trong docs/manual-tests/checkin-offline-sync.md. | I12: Đạt
A13: MC08 | B13: Tài liệu | C13: BP08 | D13: Nguyễn Lê Thế Vinh | E13: Đặc tả luồng nhập Guest List CSV: validate, phát hiện trùng, import idempotent. | F13: blueprint/design.md — "Guest list CSV import"; docs/manual-tests/guest-list-import.md | G13: 2026-06-21 | H13: Đọc design.md rồi chạy kịch bản trong docs/manual-tests/guest-list-import.md. | I13: Đạt
A14: MC09 | B14: Tài liệu | C14: BP09 | D14: Nguyễn Bảo An | E14: Thiết kế kiểm soát truy cập: 4 role và 5 điểm enforcement. | F14: blueprint/design.md — "Access Control Design" | G14: 2026-06-13 | H14: Đối chiếu ma trận role với roles.guard.ts và decorator @Roles trong controller. | I14: Đạt
A15: MC10 | B15: Tài liệu | C15: BP10 | D15: Trương Nhật Đạt | E15: Thiết kế chống tải đột biến: token bucket, ngưỡng và key giới hạn cho 80.000 người/5 phút. | F15: blueprint/design.md — Decision 7 | G15: 2026-06-20 | H15: Đối chiếu Decision 7 với rate-limit-policy.ts (7 policy, ngưỡng cụ thể). | I15: Đạt
A16: MC11 | B16: Tài liệu | C16: BP11 | D16: Trương Nhật Đạt | E16: Thiết kế Circuit Breaker và Graceful Degradation cho VNPAY/MoMo. | F16: blueprint/design.md — Decision 5 | G16: 2026-06-20 | H16: Đối chiếu Decision 5 với redis-payment-circuit-breaker.ts. | I16: Đạt
A17: MC12 | B17: Tài liệu | C17: BP12 | D17: Trương Nhật Đạt | E17: Thiết kế Idempotency Key chống trừ tiền hai lần. | F17: blueprint/design.md — Decision 4 | G17: 2026-06-20 | H17: Đối chiếu Decision 4 với redis-payment-idempotency.store.ts. | I17: Đạt
... A30: MC25 | B30: Source code | C30: IM06 | D30: Nguyễn Bảo An | E30: RolesGuard + decorator @Roles: chặn sai quyền tại tầng controller trước khi vào use-case. | F30: packages/backend/src/identity/adapters/http/guards/roles.guard.ts | G30: 2026-06-15 | H30: Gọi POST /organizer/concerts bằng token CHECKIN_STAFF, nhận 403. | I30: Đạt
A31: MC26 | B31: Pull request | C31: Mở rộng | D31: Nguyễn Bảo An | E31: PR #54 — Sàn bán lại vé (resale marketplace) và P2P escrow, ngoài yêu cầu đề. | F31: PR #54 feature/official-resale-marketplace — github.com/com-ga-xoi-mo/ticketbox-system/pull/54 | G31: 2026-07-05 | H31: Mở PR #54; chạy test/resale/resale.e2e-spec.ts. | I31: Đạt | J31: Ngoài phạm vi yêu cầu.
A32: MC27 | B32: Commit | C32: IM11 | D32: Trương Nhật Đạt | E32: Cài chống oversell: SELECT ... FOR UPDATE khóa dòng ticket_type trong transaction đặt chỗ. | F32: commit 512d263 — packages/backend/src/ordering/infrastructure/database/prisma-inventory-reservation.repository.ts | G32: 2026-06-18 | H32: git show 512d263; chạy test có case "prevents oversell when concurrent reservations serialize through the ticket type lock". | I32: Đạt
A33: MC28 | B33: Test report | C33: IM11 | D33: Trương Nhật Đạt | E33: Test chứng minh không oversell khi mua đồng thời vé cuối cùng. | F33: npx vitest run packages/backend/src/ordering/infrastructure/database/prisma-inventory-reservation.repository.spec.ts | G33: 2026-06-23 | H33: Chạy lệnh trên — 18 test pass, có case chống oversell. | I33: Đạt | J33: Đã chạy lại 2026-07-15: pass.
A34: MC29 | B34: Test report | C34: IM03 | D34: Trương Nhật Đạt | E34: Test chứng minh giới hạn vé/tài khoản không bị lách khi 2 request đồng thời. | F34: npx vitest run packages/backend/src/ordering/... repository.spec.ts + create-order.use-case.spec.ts | G34: 2026-06-23 | H34: Chạy 2 file — 29/29 test pass; có case "prevents concurrent same-user reservations from bypassing max per user after the row lock". | I34: Đạt | J34: Đã chạy lại 2026-07-15: 29/29 pass.
A35: MC30 | B35: Commit | C35: IM14 | D35: Trương Nhật Đạt | E35: Cài Idempotency payment: Redis SET NX + TTL, replay response cũ, phát hiện MISMATCH khi cùng key khác payload. | F35: commit d3e504b — packages/backend/src/payment/infrastructure/redis/redis-payment-idempotency.store.ts | G35: 2026-06-20 | H35: Chạy redis-payment-idempotency.store.spec.ts; hoặc retry 5 lần cùng Idempotency-Key và xem chỉ 1 giao dịch. | I35: Đạt
A36: MC31 | B36: Commit | C36: IM13 | D36: Trương Nhật Đạt | E36: Cài Circuit Breaker payment: Lua atomic trên Redis, 3 lỗi → OPEN, cooldown 30s, HALF_OPEN 1 request. | F36: commit 69b610c — packages/backend/src/payment/infrastructure/redis/redis-payment-circuit-breaker.ts | G36: 2026-06-20 | H36: Chạy redis-payment-circuit-breaker.spec.ts; hoặc ép provider lỗi 3 lần liên tiếp và xem mạch mở. | I36: Đạt
A37: MC32 | B37: Commit | C37: IM12 | D37: Trương Nhật Đạt | E37: Cài rate limiting: token bucket 7 policy (BROWSING 120/phút, CHECKOUT 5, PAYMENT 3...), key theo user/IP. | F37: commit 19ead99 — packages/backend/src/platform/rate-limiting/ | G37: 2026-06-20 | H37: Chạy rate-limit.interceptor.spec.ts và rate-limit-route-metadata.spec.ts (11 test pass); hoặc gọi checkout 6 lần/phút nhận 429. | I37: Đạt
A38: MC33 | B38: Test report | C38: IM12 | D38: Trương Nhật Đạt | E38: Test rate limit + circuit breaker + idempotency + cache (nhóm bảo vệ hệ thống). | F38: npx vitest run packages/backend/src/payment/... + platform/rate-limiting/ + concert-management/.../cache/ | G38: 2026-06-27 | H38: Chạy lệnh trong docs/submission-validation.md mục 2.2 — 44/44 test pass. | I38: Đạt | J38: Đã chạy lại 2026-07-15: 44/44 pass.
A39: MC34 | B39: Source code | C39: IM02 | D39: Trương Nhật Đạt | E39: Vòng đời đơn hàng: PENDING, giữ chỗ có hạn, worker hết hạn tự nhả vé. | F39: packages/backend/src/ordering/ + expire-reservations.use-case.ts | G39: 2026-06-16 | H39: Tạo đơn rồi chờ hết hạn giữ chỗ, kiểm tra reserved_quantity được trả lại. | I39: Đạt
A40: MC35 | B40: Source code | C40: IM02 | D40: Trương Nhật Đạt | E40: Tích hợp VNPay, MoMo sandbox và payment simulator; xử lý callback/IPN idempotent. | F40: packages/backend/src/payment/; docs/paid-order-recovery.md | G40: 2026-06-24 | H40: Mua vé bằng payment simulator; gọi lại callback 2 lần và kiểm tra không trừ tiền hai lần. | I40: Đạt
